Workbook

Sheet Sheet1
A3: Trend | B3: Count of Trend
A4: Material Management | B4: 95
A5: PPE | B5: 72
A6: Work at Height | B6: 67
A7: Electrical | B7: 66
A8: Barricading | B8: 60
A9: Housekeeping | B9: 60
A10: Access & Egress | B10: 37
A11: Lifting Operations | B11: 19
A12: Sharp edges | B12: 17
A13: Tools & Equipment | B13: 12
A14: Fire Safety | B14: 11
A15: Environment | B15: 10
... A21: Workbench | B21: 1
A22: (blank)
A23: Grand Total | B23: 548

Sheet CSFA Accumilative data
A1: ln | B1: Trend | C1: Observation Discription | D1: Engineer | E1: Contractors | F1: Good Citizens | G1: Violators | H1: Number of Violations | I1: Severity | J1: Violations x Severity | K1: 4 & 5 | L1: PPE Non-compliance | M1: unsafe Condes | N1: unsafe acts | O1: Contractor name | P1: Status | Q1: Danone FPR | R1: Zone | S1: Date | T1: Month
A2: 1 | B2: Material Management | C2: Stacking of material in improper way | E2: 1 | H2: 1 | I2: 3 | J2: =I2*H2 -> 3 | M2: 1 | O2: Crescon | P2: Closed | R2: Zone 1 - Chiller Building and Oil Injection | S2: 46164 | T2: May | U2: Closed
A3: =A2+1 -> 2 | B3: Material Management | C3: GI Sheet found kept untied | E3: 1 | H3: 1 | I3: 4 | J3: =I3*H3 -> 4 | K3: 1 | M3: 1 | O3: Crescon | P3: Closed | R3: Zone 1 - Chiller Building and Oil Injection | S3: 46164 | T3: May | U3: Closed
A4: =A3+1 -> 3 | B4: Barricading | C4: Uneven surface of the chiller area without barrication | E4: 1 | H4: 1 | I4: 3 | J4: =I4*H4 -> 3 | M4: 1 | O4: Crescon | P4: Closed | R4: Zone 1 - Chiller Building and Oil Injection | S4: 46164 | T4: May | U4: Closed
A5: =A4+1 -> 4 | B5: Sharp edges | C5: Sharp edges of the Electrical DB Canopy | E5: 1 | H5: 1 | I5: 4 | J5: =I5*H5 -> 4 | K5: 1 | M5: 1 | O5: Crescon | P5: Closed | R5: Zone 1 - Chiller Building and Oil Injection | S5: 46164 | T5: May | U5: Closed
A6: =A5+1 -> 5 | B6: Material Management | C6: Using of defective web-sling for lifting material | E6: 1 | F6: 5 | G6: 2 | H6: 2 | I6: 4 | J6: =I6*H6 -> 8 | K6: 1 | N6: 1 | O6: Crescon | P6: Closed | R6: Zone 1 - Chiller Building and Oil Injection | S6: 46164 | T6: May | U6: Closed | W6: 10
A7: =A6+1 -> 6 | B7: Barricading | C7: Wobling of sheets barrication due to wind | E7: 1 | H7: 1 | I7: 4 | J7: =I7*H7 -> 4 | K7: 1 | M7: 1 | O7: Crescon | P7: Closed | R7: Zone 1 - Chiller Building and Oil Injection | S7: 46164 | T7: May | U7: Closed | W7: 1
A8: =A7+1 -> 7 | B8: Barricading | C8: Insufficient barricading at roof | E8: 1 | H8: 1 | I8: 4 | J8: =I8*H8 -> 4 | K8: 1 | M8: 1 | O8: Crescon | P8: Closed | R8: Zone 1 - Chiller Building and Oil Injection | S8: 46164 | T8: May | U8: Closed | W8: 1
A9: =A8+1 -> 8 | B9: Housekeeping | C9: Poor house-keeping | E9: 1 | H9: 2 | I9: 3 | J9: =I9*H9 -> 6 | M9: 1 | O9: Crescon | P9: Closed | R9: Zone 1 - Chiller Building and Oil Injection | S9: 46164 | T9: May | U9: Closed
A10: =A9+1 -> 9 | B10: Work at Height | C10: Scaffolding with wooden planks | E10: 1 | H10: 1 | I10: 4 | J10: =I10*H10 -> 4 | K10: 1 | O10: Crescon | P10: Closed | R10: Zone 1 - Chiller Building and Oil Injection | S10: 46164 | T10: May | U10: Closed | W10: 2
A11: =A10+1 -> 10 | B11: Sharp edges | C11: Sharp edges of the Compactor Guard | E11: 1 | H11: 1 | I11: 3 | J11: =I11*H11 -> 3 | M11: 1 | O11: Crescon | P11: Closed | R11: Zone 3 - Piperack H,I & K Section, Temp. Chiller | S11: 46164 | T11: May | U11: Closed
A12: =A11+1 -> 11 | B12: Work at Height | C12: Monkey Ladder without cage | E12: 1 | H12: 1 | I12: 3 | J12: =I12*H12 -> 3 | M12: 1 | O12: Fluidline | P12: Closed | R12: Zone 3 - Piperack H,I & K Section, Temp. Chiller | S12: 46164 | T12: May | U12: Closed
A13: =A12+1 -> 12 | B13: Tools & Equipment | C13: Inspection overdue Compactor used | E13: 1 | F13: 6 | G13: 1 | H13: 1 | I13: 3 | J13: =I13*H13 -> 3 | N13: 1 | O13: Crescon | P13: Closed | R13: Zone 3 - Piperack H,I & K Section, Temp. Chiller | S13: 46164 | T13: May | U13: Closed
A14: =A13+1 -> 13 | B14: Work at Height | C14: Railings missing from the ramps | E14: 1 | H14: 1 | I14: 4 | J14: =I14*H14 -> 4 | K14: 1 | L14: 0 | M14: 1 | N14: 0 | O14: Devansh | P14: Closed | R14: Zone 1 - Chiller Building and Oil Injection | S14: 46164 | T14: May | U14: Closed | W14: 2
A15: =A14+1 -> 14 | B15: Excavation | C15: Excavated pits kept open and back filling not done | E15: 1 | H15: 1 | I15: 3 | J15: =I15*H15 -> 3 | L15: 0 | M15: 1 | N15: 0 | O15: Crescon | P15: Closed | R15: Zone 1 - Chiller Building and Oil Injection | S15: 46164 | T15: May | U15: Closed
A16: =A15+1 -> 15 | B16: Sharp edges | C16: Sharp edges of barrication sheet exposed | E16: 1 | H16: 1 | I16: 3 | J16: =I16*H16 -> 3 | L16: 0 | M16: 2 | N16: 0 | O16: Crescon | P16: Closed | R16: Zone 1 - Chiller Building and Oil Injection | S16: 46164 | T16: May | U16: Pending
A17: =A16+1 -> 16 | B17: Housekeeping | C17: 5S improper (cable trays) | E17: 1 | H17: 1 | I17: 3 | J17: =I17*H17 -> 3 | L17: 0 | M17: 1 | N17: 0 | O17: Supertech | P17: Closed | R17: Zone 1 - Chiller Building and Oil Injection | S17: 46164 | T17: May | U17: Closed
A18: =A17+1 -> 17 | B18: Environment | C18: Water logging | E18: 1 | H18: 1 | I18: 2 | J18: =I18*H18 -> 2 | M18: 1 | O18: Fluidline | P18: Closed | R18: Zone 3 - Piperack H,I & K Section, Temp. Chiller | S18: 46164 | T18: May | U18: Closed
A19: =A18+1 -> 18 | B19: Electrical | C19: Plastic chair in panel room | E19: 1 | H19: 1 | I19: 3 | J19: =I19*H19 -> 3 | M19: 1 | O19: Danone | P19: Closed | R19: Zone 1 - Chiller Building and Oil Injection | S19: 46164 | T19: May | U19: Closed | V19: =SUMIFS('CSFA Accumilative data'!T1
A20: =A19+1 -> 19 | B20: Electrical | C20: Improper Insulation | E20: 1 | H20: 1 | I20: 4 | J20: =I20*H20 -> 4 | K20: 1 | M20: 1 | O20: SPX | P20: Closed | R20: Zone 1 - Chiller Building and Oil Injection | S20: 46164 | T20: May | U20: Closed | W20: 1
A21: =A20+1 -> 20 | B21: Work at Height | C21: Cage ladder not closed | E21: 1 | H21: 1 | I21: 3 | J21: =I21*H21 -> 3 | M21: 1 | O21: Fluidline | P21: Closed | R21: Zone 3 - Piperack H,I & K Section, Temp. Chiller | S21: 46164 | T21: May | U21: Closed
A22: =A21+1 -> 21 | B22: Material Management | C22: Pannel not fixed properly at site | E22: 1 | H22: 1 | I22: 5 | J22: =I22*H22 -> 5 | K22: 1 | M22: 1 | O22: Crescon | P22: Closed | R22: Zone 1 - Chiller Building and Oil Injection | S22: 46164 | T22: May | U22: Closed | W22: 5
A23: =A22+1 -> 22 | B23: PPE | C23: Workmen without safety hand gloves | E23: 1 | F23: 2 | H23: 1 | I23: 3 | J23: =I23*H23 -> 3 | N23: 1 | O23: Crescon | P23: Closed | R23: Zone 1 - Chiller Building and Oil Injection | S23: 46164 | T23: May | U23: Closed
A24: =A23+1 -> 23 | B24: Access & Egress | C24: Permit not accessible with worker easily and found under documents after some time with no clear knowledge of work risks | E24: 1 | F24: 6 | H24: 1 | I24: 3 | J24: =I24*H24 -> 3 | O24: Fluidline | P24: Closed | R24: Zone 3 - Contractor Yard and Periphery | S24: 46164 | T24: May | U24: Closed
A25: =A24+1 -> 24 | B25: PTW & Supervision | C25: Supervisor not present for safety check while work was being done | E25: 1 | G25: 1 | H25: 1 | I25: 3 | J25: =I25*H25 -> 3 | N25: 1 | O25: Fluidline | P25: Closed | R25: Zone 3 - Contractor Yard and Periphery | S25: 46164 | T25: May | U25: Closed
A26: =A25+1 -> 25 | B26: PPE | C26: PPE not being used while marking and worker told they will use it during cutting | E26: 1 | G26: 1 | H26: 1 | I26: 3 | J26: =I26*H26 -> 3 | L26: 1 | N26: 1 | O26: Fluidline | P26: Closed | R26: Zone 3 - Contractor Yard and Periphery | S26: 46164 | T26: May | U26: Closed
A27: =A26+1 -> 26 | B27: Barricading | C27: Non Barricaded material kept near washroom area with very sharp edges and hot surface but no coverage | E27: 1 | H27: 1 | I27: 3 | J27: =I27*H27 -> 3 | M27: 1 | O27: Fluidline | P27: Closed | R27: Zone 3 - Contractor Yard and Periphery | S27: 46164 | T27: May | U27: Closed
A28: =A27+1 -> 27 | B28: Environment | C28: Inadequate illumination in contractor yard | E28: 1 | H28: 1 | I28: 3 | J28: =I28*H28 -> 3 | M28: 1 | O28: Sai Electro | P28: Closed | R28: Zone 3 - Contractor Yard and Periphery | S28: 46164 | T28: May | U28: Closed
A29: =A28+1 -> 28 | B29: Sharp edges | C29: Sharp edge on panel top sheet near container | E29: 1 | H29: 1 | I29: 4 | J29: =I29*H29 -> 4 | K29: 1 | M29: 1 | O29: Sai Electro | P29: Closed | R29: Zone 3 - Contractor Yard and Periphery | S29: 46164 | T29: May | U29: Closed | W29: 3
A30: =A29+1 -> 29 | B30: Electrical | C30: No earthing on power distribution board | E30: 1 | H30: 1 | I30: 4 | J30: =I30*H30 -> 4 | M30: 1 | O30: Esspee | P30: Closed | R30: Zone 3 - Contractor Yard and Periphery | S30: 46164 | T30: May | U30: Closed | W30: 6
A31: =A30+1 -> 30 | B31: Material Management | C31: Broken chair kept in the contractor area | E31: 1 | H31: 1 | I31: 3 | J31: =I31*H31 -> 3 | M31: 1 | O31: Esspee | P31: Closed | R31: Zone 3 - Contractor Yard and Periphery | S31: 46164 | T31: May | U31: Closed
A32: =A31+1 -> 31 | B32: Access & Egress | C32: Loose sheet lying on pathway | E32: 1 | H32: 1 | I32: 3 | J32: =I32*H32 -> 3 | M32: 1 | O32: Esspee | P32: Closed | R32: Zone 3 - Contractor Yard and Periphery | S32: 46164 | T32: May | U32: Closed
A33: =A32+1 -> 32 | B33: Material Management | C33: Wheel chokes Not used for sludge truck | E33: 1 | G33: 1 | H33: 1 | I33: 3 | J33: =I33*H33 -> 3 | M33: 1 | N33: 1 | O33: Esspee | P33: Closed | R33: Zone 3 - Contractor Yard and Periphery | S33: 46164 | T33: May | U33: Closed
A34: =A33+1 -> 33 | B34: Material Management | C34: No signage or hazard warning for stored compressed cylinders | E34: 1 | H34: 1 | I34: 3 | J34: =I34*H34 -> 3 | M34: 1 | O34: Fluidline | P34: Closed | R34: Zone 1 - Chiller Building and Oil Injection | S34: 46164 | T34: May | U34: Pending
A35: =A34+1 -> 34 | B35: Housekeeping | C35: Material stored in oil injection area without following 5S | E35: 1 | H35: 1 | I35: 1 | J35: =I35*H35 -> 1 | M35: 1 | O35: Devansh | P35: Pending | R35: Zone 1 - Chiller Building and Oil Injection | S35: 46165 | T35: May | U35: Closed
A36: =A35+1 -> 35 | B36: Tools & Equipment | C36: Not using wise while cutting square pipe with grinder by holding | E36: 1 | F36: 5 | G36: 1 | H36: 1 | I36: 4 | J36: =I36*H36 -> 4 | K36: 1 | N36: 1 | O36: CCEPL | P36: Closed | R36: Zone 3 - Contractor Yard and Periphery | S36: 46165 | T36: May | U36: Closed | W36: 2
A37: =A36+1 -> 36 | B37: Sharp edges | C37: Sharp edges of the GI sheet exposed | E37: 1 | H37: 1 | I37: 3 | J37: =I37*H37 -> 3 | M37: 1 | O37: Fluidline | P37: Closed | R37: Zone 3 - Piperack H,I & K Section, Temp. Chiller | S37: 46165 | T37: May | U37: Closed
A38: =A37+1 -> 37 | B38: Environment | C38: Water logging near cooling tower | E38: 1 | H38: 1 | I38: 3 | J38: =I38*H38 -> 3 | M38: 1 | O38: Fluidline | P38: Closed | R38: Zone 3 - Piperack H,I & K Section, Temp. Chiller | S38: 46165 | T38: May | U38: Closed
A39: =A38+1 -> 38 | B39: Housekeeping | C39: Poor house keeping - Unwanted material kept in the way | E39: 1 | H39: 1 | I39: 2 | J39: =I39*H39 -> 2 | M39: 1 | O39: Crescon | P39: Closed | R39: Zone 3 - Piperack H,I & K Section, Temp. Chiller | S39: 46165 | T39: May | U39: Closed
A40: =A39+1 -> 39 | B40: Housekeeping | C40: House Keeping to improve | E40: 1 | H40: 1 | I40: 2 | J40: =I40*H40 -> 2 | M40: 1 | O40: SPX | P40: Closed | R40: Zone 4 - Oil Blending, Panel Room, Refrigeration Building & Roof Areas | S40: 46165 | T40: May | U40: Closed
...

Sheet Severity info
A1: Severity | B1: (All)
A3: Count of Contractor name | B3: Column Labels
B4: <22-05-2026 | C4: May | D4: Jun | E4: Grand Total
A6: Row Labels
A7: Aalanna | C7: 19 | D7: 37 | E7: 56
A8: All | D8: 5 | E8: 5
A9: CCEPL | C9: 8 | D9: 14 | E9: 22
A10: Crescon | C10: 48 | D10: 72 | E10: 120
A11: Danone | C11: 6 | D11: 46 | E11: 52
A12: Devansh | C12: 7 | D12: 6 | E12: 13
A13: Esspee | C13: 14 | D13: 33 | E13: 47
A14: Fluidline | C14: 31 | D14: 110 | E14: 141
A15: GEA | C15: 5 | D15: 43 | E15: 48
A16: Maptrix | C16: 1 | E16: 1 | G16: Average severity based upon Accumilative sheet
A17: Project Management & Structure | D17: 3 | E17: 3 | U17: Vendor-monthly observations
A18: Sai Electro | C18: 3 | E18: 3 | G18: DO NOT TOUCH | I18: Avg. Severity Score YTD | J18: Unsafe acts | K18: July16th-July30th | L18: unsafe acts | N18: DO NOT TOUCH | O18: SEVERITY | P18: NO. OF OBS | Q18: NO. OF CLOSED | U18: Vendor | V18: Month | W18: 4&5 observations | X18: Change from prev month
A19: SPX | C19: 8 | D19: 20 | E19: 28 | G19: Vendor | H19: EssPee | I19: =SUMIFS('CSFA Accumilative data'!I:I,'CSFA Accumilative data'!O:O,'Severity info'!H19)/COUNTIFS('CSFA Accumilative data'!O:O,'Severity info'!H19) -> 2.6595745 | J19: =SUMIFS('CSFA Accumilative data'!N:N,'CSFA Accumilative data'!O:O,'Severity info'!H19) -> 15 | K19: =SUMIFS('CSFA Accumilative data'!$I$369:$I$553,'CSFA Accumilative data'!$O$369:$O$553,'Severity info'!H19)/COUNTIFS('CSFA Accumilative data'!$O$369:$O$553,'Severity info'!H19) -> 2.6923077 | L19: =SUMIFS('CSFA Accumilative data'!$N$369:$N$553,'CSFA Accumilative data'!$O$369:$O$553,'Severity info'!H19) -> 4 | N19: Closed | O19: 4 | P19: =COUNTIFS('CSFA Accumilative data'!I:I,'Severity info'!O19) -> 74 | Q19: =COUNTIFS('CSFA Accumilative data'!I:I,'Severity info'!O19,'CSFA Accumilative data'!P:P,'Severity info'!N19) -> 65 | U19: Aalanna | V19: May | W19: =SUMIFS('CSFA Accumilative data'!K:K,'CSFA Accumilative data'!T:T,'Severity info'!V19,'CSFA Accumilative data'!O:O,'Severity info'!U19) -> 4
A20: Supertech | C20: 2 | D20: 1 | E20: 3 | H20: Crescon | I20: =SUMIFS('CSFA Accumilative data'!I:I,'CSFA Accumilative data'!O:O,'Severity info'!H20)/COUNTIFS('CSFA Accumilative data'!O:O,'Severity info'!H20) -> 3.025 | J20: =SUMIFS('CSFA Accumilative data'!N:N,'CSFA Accumilative data'!O:O,'Severity info'!H20) -> 54 | K20: =SUMIFS('CSFA Accumilative data'!$I$369:$I$553,'CSFA Accumilative data'!$O$369:$O$553,'Severity info'!H20)/COUNTIFS('CSFA Accumilative data'!$O$369:$O$553,'Severity info'!H20) -> 3.0857143 | L20: =SUMIFS('CSFA Accumilative data'!$N$369:$N$553,'CSFA Accumilative data'!$O$369:$O$553,'Severity info'!H20) -> 15 | N20: Closed | O20: 5 | P20: =COUNTIFS('CSFA Accumilative data'!I:I,'Severity info'!O20) -> 14 | Q20: =COUNTIFS('CSFA Accumilative data'!I:I,'Severity info'!O20,'CSFA Accumilative data'!P:P,'Severity info'!N20) -> 13 | U20: CCEPL | V20: May | W20: =SUMIFS('CSFA Accumilative data'!K:K,'CSFA Accumilative data'!T:T,'Severity info'!V20,'CSFA Accumilative data'!O:O,'Severity info'!U20) -> 2
A21: (blank) | H21: Fluidline | I21: =SUMIFS('CSFA Accumilative data'!I:I,'CSFA Accumilative data'!O:O,'Severity info'!H21)/COUNTIFS('CSFA Accumilative data'!O:O,'Severity info'!H21) -> 2.9716312 | J21: =SUMIFS('CSFA Accumilative data'!N:N,'CSFA Accumilative data'!O:O,'Severity info'!H21) -> 57 | K21: =SUMIFS('CSFA Accumilative data'!$I$369:$I$553,'CSFA Accumilative data'!$O$369:$O$553,'Severity info'!H21)/COUNTIFS('CSFA Accumilative data'!$O$369:$O$553,'Severity info'!H21) -> 2.9607843 | L21: =SUMIFS('CSFA Accumilative data'!$N$369:$N$553,'CSFA Accumilative data'!$O$369:$O$553,'Severity info'!H21) -> 20 | O21: Sum: | P21: =P19+P20 -> 88 | Q21: =Q19+Q20 -> 78 | R21: No. of days: | S21: =COUNTA(_xlfn.UNIQUE('CSFA Accumilative data'!S:S)) -> 37 | U21: Crescon | V21: May | W21: =SUMIFS('CSFA Accumilative data'!K:K,'CSFA Accumilative data'!T:T,'Severity info'!V21,'CSFA Accumilative data'!O:O,'Severity info'!U21) -> 11
A22: Crescon | D22: 2 | E22: 2 | H22: CCEPL | I22: =SUMIFS('CSFA Accumilative data'!I:I,'CSFA Accumilative data'!O:O,'Severity info'!H22)/COUNTIFS('CSFA Accumilative data'!O:O,'Severity info'!H22) -> 3 | J22: =SUMIFS('CSFA Accumilative data'!N:N,'CSFA Accumilative data'!O:O,'Severity info'!H22) -> 8 | K22: =SUMIFS('CSFA Accumilative data'!$I$369:$I$553,'CSFA Accumilative data'!$O$369:$O$553,'Severity info'!H22)/COUNTIFS('CSFA Accumilative data'!$O$369:$O$553,'Severity info'!H22) -> 3.4 | L22: =SUMIFS('CSFA Accumilative data'!$N$369:$N$553,'CSFA Accumilative data'!$O$369:$O$553,'Severity info'!H22) -> 2 | R22: H.OBS/DAY | S22: =P21/S21 -> 2.3783784 | U22: EssPee | V22: May | W22: =SUMIFS('CSFA Accumilative data'!K:K,'CSFA Accumilative data'!T:T,'Severity info'!V22,'CSFA Accumilative data'!O:O,'Severity info'!U22) -> 0
A23: Satnam | D23: 3 | E23: 3 | H23: Aalanna | I23: =SUMIFS('CSFA Accumilative data'!I:I,'CSFA Accumilative data'!O:O,'Severity info'!H23)/COUNTIFS('CSFA Accumilative data'!O:O,'Severity info'!H23) -> 2.5535714 | J23: =SUMIFS('CSFA Accumilative data'!N:N,'CSFA Accumilative data'!O:O,'Severity info'!H23) -> 7 | K23: =SUMIFS('CSFA Accumilative data'!$I$369:$I$553,'CSFA Accumilative data'!$O$369:$O$553,'Severity info'!H23)/COUNTIFS('CSFA Accumilative data'!$O$369:$O$553,'Severity info'!H23) -> 2.125 | L23: =SUMIFS('CSFA Accumilative data'!$N$369:$N$553,'CSFA Accumilative data'!$O$369:$O$553,'Severity info'!H23) -> 2 | R23: H.CLOSURE | S23: =Q21/P21*100 -> 88.636364 | U23: Devansh | V23: May | W23: =SUMIFS('CSFA Accumilative data'!K:K,'CSFA Accumilative data'!T:T,'Severity info'!V23,'CSFA Accumilative data'!O:O,'Severity info'!U23) -> 1
A24: ESSWIN | D24: 2 | E24: 2 | H24: SPX | I24: =SUMIFS('CSFA Accumilative data'!I:I,'CSFA Accumilative data'!O:O,'Severity info'!H24)/COUNTIFS('CSFA Accumilative data'!O:O,'Severity info'!H24) -> 2.2142857 | J24: =SUMIFS('CSFA Accumilative data'!N:N,'CSFA Accumilative data'!O:O,'Severity info'!H24) -> 8 | K24: =SUMIFS('CSFA Accumilative data'!$I$369:$I$553,'CSFA Accumilative data'!$O$369:$O$553,'Severity info'!H24)/COUNTIFS('CSFA Accumilative data'!$O$369:$O$553,'Severity info'!H24) -> 2 | L24: =SUMIFS('CSFA Accumilative data'!$N$369:$N$553,'CSFA Accumilative data'!$O$369:$O$553,'Severity info'!H24) -> 2 | N24: unsafe act/cond | O24: =SUM('CSFA Accumilative data'!N:N)/SUM('CSFA Accumilative data'!M:M) -> 0.47826087 | U24: Fluidline | V24: May | W24: =SUMIFS('CSFA Accumilative data'!K:K,'CSFA Accumilative data'!T:T,'Severity info'!V24,'CSFA Accumilative data'!O:O,'Severity info'!U24) -> 2
A25: Common area | D25: 1 | E25: 1 | H25: GEA | I25: =SUMIFS('CSFA Accumilative data'!I:I,'CSFA Accumilative data'!O:O,'Severity info'!H25)/COUNTIFS('CSFA Accumilative data'!O:O,'Severity info'!H25) -> 2.8125 | J25: =SUMIFS('CSFA Accumilative data'!N:N,'CSFA Accumilative data'!O:O,'Severity info'!H25) -> 16 | K25: =SUMIFS('CSFA Accumilative data'!$I$369:$I$553,'CSFA Accumilative data'!$O$369:$O$553,'Severity info'!H25)/COUNTIFS('CSFA Accumilative data'!$O$369:$O$553,'Severity info'!H25) -> 3.1071429 | L25: =SUMIFS('CSFA Accumilative data'!$N$369:$N$553,'CSFA Accumilative data'!$O$369:$O$553,'Severity info'!H25) -> 10 | N25: unsafe acts: | O25: =SUM('CSFA Accumilative data'!N:N) -> 176 | U25: GEA | V25: May | W25: =SUMIFS('CSFA Accumilative data'!K:K,'CSFA Accumilative data'!T:T,'Severity info'!V25,'CSFA Accumilative data'!O:O,'Severity info'!U25) -> 1
A26: Grand Total | C26: 152 | D26: 398 | E26: 550 | H26: Devansh | I26: =SUMIFS('CSFA Accumilative data'!I:I,'CSFA Accumilative data'!O:O,'Severity info'!H26)/COUNTIFS('CSFA Accumilative data'!O:O,'Severity info'!H26) -> 2.4615385 | J26: =SUMIFS('CSFA Accumilative data'!N:N,'CSFA Accumilative data'!O:O,'Severity info'!H26) -> 0 | K26: =SUMIFS('CSFA Accumilative data'!I375:I560,'CSFA Accumilative data'!O375:O560,'Severity info'!H26)/(COUNTIFS('CSFA Accumilative data'!O375:O560,'Severity info'!H26)+0.000000001) -> 0 | L26: =SUMIFS('CSFA Accumilative data'!N371:N545,'CSFA Accumilative data'!O371:O545,'Severity info'!H26) -> 0 | U26: SPX | V26: May | W26: =SUMIFS('CSFA Accumilative data'!K:K,'CSFA Accumilative data'!T:T,'Severity info'!V26,'CSFA Accumilative data'!O:O,'Severity info'!U26) -> 1
G27: ZONE | H27: Zone 1 - Chiller Building and Oil Injection | I27: =SUMIFS('CSFA Accumilative data'!I:I,'CSFA Accumilative data'!R:R,'Severity info'!H27)/COUNTIFS('CSFA Accumilative data'!R:R,'Severity info'!H27) -> 2.9528302 | J27: =SUMIFS('CSFA Accumilative data'!N:N,'CSFA Accumilative data'!R:R,'Severity info'!H27) -> 69 | K27: =SUMIFS('CSFA Accumilative data'!$I$369:$I$553,'CSFA Accumilative data'!$R$369:$R$553,'Severity info'!H27)/COUNTIFS('CSFA Accumilative data'!$R$369:$R$553,'Severity info'!H27) -> 3.0123457 | L27: =SUMIFS('CSFA Accumilative data'!$N$369:$N$553,'CSFA Accumilative data'!$R$369:$R$553,'Severity info'!H27) -> 30 | U27: Aalanna | V27: June | W27: =SUMIFS('CSFA Accumilative data'!K:K,'CSFA Accumilative data'!T:T,'Severity info'!V27,'CSFA Accumilative data'!O:O,'Severity info'!U27) -> 5 | X27: =Vend_monthly_obs[[#This Row],[4&5 observations]]-W19 -> 1 | Z27: Aalanna | AA27: 5 | AB27: 1
H28: Zone 2 - Evaporator Building | I28: =SUMIFS('CSFA Accumilative data'!I:I,'CSFA Accumilative data'!R:R,'Severity info'!H28)/COUNTIFS('CSFA Accumilative data'!R:R,'Severity info'!H28) -> 2.776 | J28: =SUMIFS('CSFA Accumilative data'!N:N,'CSFA Accumilative data'!R:R,'Severity info'!H28) -> 34 | K28: =SUMIFS('CSFA Accumilative data'!$I$369:$I$553,'CSFA Accumilative data'!$R$369:$R$553,'Severity info'!H28)/COUNTIFS('CSFA Accumilative data'!$R$369:$R$553,'Severity info'!H28) -> 2.877193 | L28: =SUMIFS('CSFA Accumilative data'!$N$369:$N$553,'CSFA Accumilative data'!$R$369:$R$553,'Severity info'!H28) -> 15 | U28: CCEPL | V28: June | W28: =SUMIFS('CSFA Accumilative data'!K:K,'CSFA Accumilative data'!T:T,'Severity info'!V28,'CSFA Accumilative data'!O:O,'Severity info'!U28) -> 2 | X28: =Vend_monthly_obs[[#This Row],[4&5 observations]]-W20 -> 0 | Z28: CCEPL | AA28: 2 | AB28: 0
H29: Zone 3 - Contractor Yard and Periphery | I29: =SUMIFS('CSFA Accumilative data'!I:I,'CSFA Accumilative data'!R:R,'Severity info'!H29)/COUNTIFS('CSFA Accumilative data'!R:R,'Severity info'!H29) -> 2.6489362 | J29: =SUMIFS('CSFA Accumilative data'!N:N,'CSFA Accumilative data'!R:R,'Severity info'!H29) -> 25 | K29: =SUMIFS('CSFA Accumilative data'!$I$369:$I$553,'CSFA Accumilative data'!$R$369:$R$553,'Severity info'!H29)/COUNTIFS('CSFA Accumilative data'!$R$369:$R$553,'Severity info'!H29) -> 2.5357143 | L29: =SUMIFS('CSFA Accumilative data'!$N$369:$N$553,'CSFA Accumilative data'!$R$369:$R$553,'Severity info'!H29) -> 4 | U29: Crescon | V29: June | W29: =SUMIFS('CSFA Accumilative data'!K:K,'CSFA Accumilative data'!T:T,'Severity info'!V29,'CSFA Accumilative data'!O:O,'Severity info'!U29) -> 15 | X29: =Vend_monthly_obs[[#This Row],[4&5 observations]]-W21 -> 4 | Z29: Crescon | AA29: 14 | AB29: 3
H30: Zone 4 - Oil Blending, Panel Room, Refrigeration Building & Roof Areas | I30: =SUMIFS('CSFA Accumilative data'!I:I,'CSFA Accumilative data'!R:R,'Severity info'!H30)/COUNTIFS('CSFA Accumilative data'!R:R,'Severity info'!H30) -> 2.5681818 | J30: =SUMIFS('CSFA Accumilative data'!N:N,'CSFA Accumilative data'!R:R,'Severity info'!H30) -> 15 | K30: =SUMIFS('CSFA Accumilative data'!$I$369:$I$553,'CSFA Accumilative data'!$R$369:$R$553,'Severity info'!H30)/COUNTIFS('CSFA Accumilative data'!$R$369:$R$553,'Severity info'!H30) -> 2.4210526 | L30: =SUMIFS('CSFA Accumilative data'!$N$369:$N$553,'CSFA Accumilative data'!$R$369:$R$553,'Severity info'!H30) -> 9 | U30: EssPee | V30: June | W30: =SUMIFS('CSFA Accumilative data'!K:K,'CSFA Accumilative data'!T:T,'Severity info'!V30,'CSFA Accumilative data'!O:O,'Severity info'!U30) -> 2 | X30: =Vend_monthly_obs[[#This Row],[4&5 observations]]-W22 -> 2 | Z30: EssPee | AA30: 2 | AB30: 2
U31: Devansh | V31: June | W31: =SUMIFS('CSFA Accumilative data'!K:K,'CSFA Accumilative data'!T:T,'Severity info'!V31,'CSFA Accumilative data'!O:O,'Severity info'!U31) -> 2 | X31: =Vend_monthly_obs[[#This Row],[4&5 observations]]-W23 -> 1 | Z31: Devansh | AA31: 2 | AB31: 1
U32: Fluidline | V32: June | W32: =SUMIFS('CSFA Accumilative data'!K:K,'CSFA Accumilative data'!T:T,'Severity info'!V32,'CSFA Accumilative data'!O:O,'Severity info'!U32) -> 20 | X32: =Vend_monthly_obs[[#This Row],[4&5 observations]]-W24 -> 18 | Z32: Fluidline | AA32: 20 | AB32: 18
U33: GEA | V33: June | W33: =SUMIFS('CSFA Accumilative data'!K:K,'CSFA Accumilative data'!T:T,'Severity info'!V33,'CSFA Accumilative data'!O:O,'Severity info'!U33) -> 7 | X33: =Vend_monthly_obs[[#This Row],[4&5 observations]]-W25 -> 6 | Z33: GEA | AA33: 7 | AB33: 6
N34: Zone | O34: Avg. Severity Score | Q34: stat | R34: Value | U34: SPX | V34: June | W34: =SUMIFS('CSFA Accumilative data'!K:K,'CSFA Accumilative data'!T:T,'Severity info'!V34,'CSFA Accumilative data'!O:O,'Severity info'!U34) -> 1 | X34: =Vend_monthly_obs[[#This Row],[4&5 observations]]-W26 -> 0 | Z34: SPX | AA34: 1 | AB34: 0
N35: Zone 1 - Chiller Building and Oil Injection | O35: =I27 -> 2.9528302 | Q35: H.OBS/DAY | R35: =S22 -> 2.3783784
N36: Zone 2 - Evaporator Building | O36: =I28 -> 2.776 | Q36: H.CLOSURE | R36: =S23 -> 88.636364
N37: Zone 3 - Contractor Yard and Periphery | O37: =I29 -> 2.6489362 | Q37: unsafe act/cond | R37: =O24 -> 0.47826087
N38: Zone 4 - Oil Blending, Panel Room, Refrigeration Building & Roof Areas | O38: =I30 -> 2.5681818 | Q38: Total 4&5 | R38: =P21 -> 88
Q39: tot.no. of vend | R39: 13
H40: Trends | K40: Contracotr Severity | Q40: Avg manpower/day
H42: Category | I42: Count | K42: Vendor | L42: Avg. Severity Score
H43: =Sheet1!A4 -> Material Management | I43: =Sheet1!B4 -> 95 | K43: EssPee | L43: =I19 -> 2.6595745
...

Sheet Sheet3
A1: Contractor name | B1: Crescon
A3: Row Labels | B3: Count of Observation Discription
A4: 1 | B4: 26
A5: (blank) | B5: 94
A6: Grand Total | B6: 120
B28: Date | C28: Count of Observation Discription
B29: 22-May | C29: 33
B30: 23-May | C30: 12
B31: 25-May | C31: 25
B32: 26-May | C32: 18
B33: 27-May | C33: 16
B34: 28-May | C34: 13
B35: 29-May | C35: 18
B36: 30-May | C36: 21
B37: 01-Jun | C37: 23
B38: 02-Jun | C38: 28
B39: 03-Jun | C39: 27
B40: 04-Jun | C40: 10
B41: 46178 | C41: 5
B42: 46179 | C42: 20

Sheet Sheet4
A2: Fall of Material
A3: Sharp Edges | I3: Trend
A4: Tools & Tackles | I4: Fall of Material
A5: Fall of Material | I5: Sharp Edges | K5: Row Labels | L5: Count of Trend | N5: Row Labels | O5: Count of Trend
A6: Barrication | I6: Tools & Tackles | K6: Barrication | L6: 4 | N6: Electrical Safety | O6: 13
A7: Scaffold Safety | I7: Fall of Material | K7: Electrical Safety | L7: 13 | N7: Fall of Material | O7: 10
A8: Fall from Height | I8: Barrication | K8: Ergonomic Hazard | L8: 1 | N8: Sharp Edges | O8: 6
A9: Electrical Safety | I9: Scaffold Safety | K9: Even Surface | L9: 3 | N9: Barrication | O9: 4
A10: Electrical Safety | I10: Fall from Height | K10: Fabrication | L10: 2 | N10: Fall from Height | O10: 4
A11: Sharp Edges | I11: Electrical Safety | K11: Fall from Height | L11: 4 | N11: PPE | O11: 4
A12: Fabrication | I12: Electrical Safety | K12: Fall of Material | L12: 10 | N12: Even Surface | O12: 3
A13: Supervision | I13: Sharp Edges | K13: Fire Safety | L13: 1 | N13: Scaffold Safety | O13: 3
A14: Sharp Edges | I14: Electrical Safety | K14: Illumination | L14: 1 | N14: Fabrication | O14: 2
A15: Sharp Edges | I15: Fabrication | K15: Line of Fire | L15: 1 | N15: Tools & Tackles | O15: 2
A16: Electrical Safety | I16: Supervision | K16: PPE | L16: 4 | N16: Ergonomic Hazard | O16: 1
A17: Tools & Tackles | I17: Sharp Edges | K17: Scaffold Safety | L17: 3 | N17: Fire Safety | O17: 1
... A21: Electrical Safety | I21: Barrication | K21: Tools & Tackles | L21: 2 | N21: Supervision | O21: 1
A22: Scaffold Safety | I22: Slip, Trip and Fall | K22: Grand Total | L22: 57
A23: Electrical Safety | I23: Sharp Edges
A24: Electrical Safety | I24: Electrical Safety
A25: Fall from Height | I25: Scaffold Safety
A26: Fire Safety | I26: Fabrication
A27: Ergonomic Hazard | I27: Electrical Safety
A28: Electrical Safety | I28: Electrical Safety
A29: Illumination | I29: Fall from Height
A30: Even Surface | I30: Fire Safety
A31: Fall of Material | I31: Ergonomic Hazard
A32: Fall of Material | I32: Electrical Safety
A33: Fall of Material | I33: Illumination
A34: Fall from Height | I34: Even Surface
... A56: Sharp Edges | I56: Electrical Safety
I57: Fall of Material
I58: Electrical Safety
I59: Fall of Material
I60: Sharp Edges

Sheet Sheet5
A1: 4 & 5 | B1: 1
A3: Count of Status | B3: Column Labels | S3: Row Labels | T3: Count of Status
B4: May | C4: Jun | D4: Grand Total | K4: 2.4 | S4: 5S | T4: 66
K5: 2.7 | S5: Barrication | T5: 41
A6: Row Labels | K6: 3 | S6: Slip, Trip and Fall | T6: 41
A7: Aalanna | B7: 4 | C7: 4 | D7: 8 | K7: 3.1 | S7: PPE | T7: 40
A8: CCEPL | B8: 2 | D8: 2 | K8: 2.6 | S8: Electrical Safety | T8: 38
A9: Crescon | B9: 11 | C9: 8 | D9: 19 | K9: 2.9 | S9: Fall from Height | T9: 24
A10: Crescon | C10: 1 | D10: 1 | K10: 2.9 | S10: Fall of Material | T10: 20
A11: Danone | C11: 4 | D11: 4 | K11: 2.2 | S11: Sharp Edges | T11: 20
A12: Devansh | B12: 1 | C12: 2 | D12: 3 | K12: 3.1 | S12: Other | T12: 13
A13: Esspee | C13: 2 | D13: 2 | K13: 2.9 | S13: Scaffold Safety | T13: 11
A14: Fluidline | B14: 2 | C14: 15 | D14: 17 | K14: 2.9 | S14: Fire Safety | T14: 9
A15: GEA | B15: 1 | C15: 1 | D15: 2 | K15: 2.9 | S15: Illumination | T15: 8
A16: Sai Electro | B16: 1 | D16: 1 | K16: 2.1 | S16: Tools & Tackles | T16: 8
A17: SPX | B17: 1 | D17: 1 | K17: 2.7 | S17: Human Error | T17: 7
A18: Grand Total | B18: 23 | C18: 37 | D18: 60 | K18: 2.9 | S18: Road Safety | T18: 7
S19: Safe Observation | T19: 6
S20: Ergonomic Hazard | T20: 4
S21: Even Surface | T21: 4
S22: Hygiene | T22: 4
S23: Line of Fire | T23: 4
S24: Material Handling | T24: 4
S25: Supervision | T25: 4
S26: Fabrication | T26: 3
S27: Wellbeing | T27: 3
S28: Lifting Operation | T28: 2
S29: Paralle Work | T29: 2
S30: Water Logging | T30: 2
... S39: Stability | T39: 1
