Workbook

Sheet PTW
A1: Id | B1: Start time | C1: Completion time | D1: Email | E1: Name | F1: PTW Date | G1: PTW Issued Time | H1: PTW Authorizer Time | I1: PTW No | J1: Work Description | K1: Work Location | L1: Contractor Name | M1: PTW Authorizer | N1: Permit Issuer | O1: Special permission | P1: PTW Type | Q1: Risk | R1: Remarks
A2: 1 | B2: 46167.87 | C2: 46167.873 | D2: anonymous | F2: 46167 | G2: 9:00 am | I2: 24389 | J2: Housekeeping, steelcutting, excavation | K2: New chiller building | L2: Crescon | M2: Akshey | N2: Akshey | O2: No | P2: General work, Hot work, Work at height, Excavation work | Q2: Medium Risk
A3: 2 | B3: 46168.439 | C3: 46168.442 | D3: anonymous | F3: 46168 | G3: 9:15 Am | I3: 23584 | J3: Wall dismentle, chipping for insert plat, debris Material shifting, house keeping, breking for gread slab for foundation | K3: Evaporator | L3: Aalanna | M3: Akash | N3: Shahnawaz | O3: Yes | P3: General work, Hot work, Work at height | Q3: Medium Risk
A4: 3 | B4: 46168.526 | C4: 46168.536 | D4: anonymous | F4: 46168 | G4: 9:00Am | I4: 5151 | J4: Housekeeping, excavation, concreting, scaffolding staircase,steel fixing , brick work, hard berrication, loading and unloading coulem hammering | K4: New chiller areas | L4: Crescon | M4: Akash | N4: Shahnawaz | O4: No | P4: General work, Hot work, Work at height, Excavation work | Q4: Medium Risk
A5: 4 | B5: 46168.603 | C5: 46168.607 | D5: anonymous | F5: 46168 | G5: 9:42 | I5: 22840 | J5: Platform Plate fixing, Scaffolding Erection and Dismantle, Materials Shifting from store to Evaporate Section | K5: Evaporator | L5: GEA | M5: Shahnawaz | N5: Ajay | O5: No | P5: General work, Hot work, Work at height | Q5: Medium Risk
A6: 5 | B6: 46168.655 | C6: 46168.656 | D6: anonymous | F6: 46168 | G6: 9:12 | I6: 22841 | J6: Pipe Storage rack fabrication and housekeeping | K6: Near Filter Cleaning | L6: GEA | M6: Ajay | N6: Akshey | O6: No | P6: Hot work, General work | Q6: Medium Risk
A7: 6 | B7: 46168.831 | C7: 46168.833 | D7: anonymous | F7: 46168 | G7: 9:15 am | I7: 5152 | J7: Pipe reaction, material shifting lifting and unloading | K7: Near by Chiller building | L7: Crescon | M7: Akshey | N7: Akshey | O7: No | P7: Work at height | Q7: Medium Risk
A8: 7 | B8: 46169.405 | C8: 46169.406 | D8: anonymous | F8: 46169 | G8: 09:20 | I8: 5101 | J8: Breaking for gread Slab housekeeping & material shifting | K8: Evaporation | L8: Aalanna | M8: Danish | N8: Surender | O8: No | P8: Hot work, General work | Q8: Medium Risk
A9: 8 | B9: 46169.46 | C9: 46169.462 | D9: anonymous | F9: 46169 | G9: 9:30 | I9: 22844 | J9: Platform Plate fixing, platform shifting | K9: Evaporator | L9: GEA | M9: Ajay | N9: Surender | O9: No | P9: General work, Hot work, Work at height | Q9: Medium Risk
A10: 9 | B10: 46169.462 | C10: 46169.465 | D10: anonymous | F10: 46169 | G10: 9:40 | I10: 22843 | J10: RIO Panel Shifting & MCC | K10: New chiller Building | L10: GEA | M10: Ajay | N10: Surender | O10: No | P10: General work | Q10: Medium Risk
A11: 10 | B11: 46169.465 | C11: 46169.467 | D11: anonymous | F11: 46169 | G11: 9:40 | I11: 22845 | J11: Pipe rack fabrication material shifting | K11: New Filter Cleaning | L11: GEA | M11: Ajay | N11: Surender | O11: No | P11: Hot work, General work | Q11: Medium Risk
A12: 11 | B12: 46169.784 | C12: 46169.786 | D12: anonymous | F12: 46169 | G12: 9:00. AM | I12: 5154 | J12: Colom habring, excavation, brick work, steel cutting, barricade, stuttering work, | K12: New chiller building | L12: Crescon | M12: Akash | N12: Danish | O12: No | P12: General work, Hot work, Work at height, Excavation work | Q12: Medium Risk
A13: 12 | B13: 46169.784 | C13: 46169.788 | D13: anonymous | F13: 46169 | G13: 9:15 AM | I13: 5156 | J13: Pipe erection, material loading and unloading by farana | K13: New chiller building | L13: Crescon | M13: Danish | N13: Akash | O13: No | P13: Work at height | Q13: High Risk
... A21: 20 | B21: 46170.594 | C21: 46170.596 | D21: anonymous | F21: 46170 | G21: 9:30 | I21: 5453 | J21: Manual material shifting, wall repair and plaster work | K21: Boilar Terrace | L21: CCEPL | M21: Tajinder | N21: Shahnawaz | O21: No | P21: General work | Q21: Medium Risk
A22: 21 | B22: 46170.638 | C22: 46170.64 | D22: anonymous | F22: 46170 | G22: 3:00 | I22: 5454 | J22: Manual material shifting, soil feeling and digging , brick work, housekeeping | K22: Canteen Out Side | L22: CCEPL | M22: Shahnawaz | N22: Abhay | O22: No | P22: General work | Q22: Low Risk | R22: Work in progress
A23: 22 | B23: 46170.669 | C23: 46170.67 | D23: anonymous | F23: 46170 | G23: 12:20 | I23: 28848 | J23: Platform material unloading | K23: Near boiler area | L23: GEA | M23: Akash | N23: Surender | O23: No | P23: General work, Work at height | Q23: Medium Risk
A24: 23 | B24: 46170.84 | C24: 46170.842 | D24: anonymous | F24: 46170 | G24: 9:00 AM | I24: 5157 | J24: Excavation, shuttering, rainforcement, loading and unloading | K24: New chiller building | L24: Crescon | M24: Akshey | N24: Shahnawaz | O24: No | P24: General work, Hot work, Excavation work | Q24: Medium Risk
A25: 24 | B25: 46170.842 | C25: 46170.844 | D25: anonymous | F25: 46170 | G25: 9:00 AM | I25: 5158 | J25: Soil GJB compection | K25: Canteen area | L25: Crescon | M25: Akshey | N25: Shahnawaz | O25: No | P25: General work | Q25: Medium Risk
A26: 25 | B26: 46171.43 | C26: 46171.433 | D26: anonymous | F26: 46171 | G26: 09:40 | I26: 5103 | J26: Chipping for slab, steel fixing, cutting, housekeeping, material shifting | K26: Evaporator | L26: Aalanna | M26: Akshey | N26: Akash | O26: No | P26: General work, Hot work, Work at height | Q26: Medium Risk
A27: 26 | B27: 46171.437 | C27: 46171.438 | D27: anonymous | F27: 46171 | G27: 9:40 | I27: 23102 | J27: Frem fabrication pipe shifting | K27: Near Filter Cleaning | L27: GEA | M27: Akash | N27: Akshey | O27: No | P27: Hot work, General work | Q27: Medium Risk
A28: 27 | B28: 46171.456 | C28: 46171.473 | D28: anonymous | F28: 46171 | G28: 9:20 | I28: 5455 | J28: Manual material shifting, brick work, scaffolding erection and modification, metro sheet remove, housekeeping | K28: Milk tank area | L28: CCEPL | M28: Danish | N28: Akash | O28: No | P28: General work, Work at height | Q28: Low Risk
A29: 28 | B29: 46171.474 | C29: 46171.475 | D29: anonymous | F29: 46171 | G29: 9:50 | I29: 5456 | J29: Manual material shifting, repair and plaster work, housekeeping | K29: Boilar Terrace | L29: CCEPL | M29: Danish | N29: Akash | O29: No | P29: General work | Q29: Low Risk
A30: 29 | B30: 46171.533 | C30: 46171.535 | D30: anonymous | F30: 46171 | G30: 10:30 am | I30: 5013 | J30: Frame fabrication, grinding, cutting, welding, material shifting, housekeeping | K30: ETP | L30: Esspee | M30: Akash | N30: Akshey | O30: No | P30: Hot work, General work | Q30: Low Risk
A31: 30 | B31: 46171.796 | C31: 46171.8 | D31: anonymous | F31: 46171 | G31: 9:30 Am | I31: 5415 | J31: Hand railing fabrication and installation for cooling tower | K31: MWRS chiller area | L31: Fluid-line | M31: Danish | N31: Tajinder | O31: No | P31: General work, Hot work, Work at height | Q31: High Risk
A32: 31 | B32: 46171.8 | C32: 46171.806 | D32: anonymous | F32: 46171 | G32: 10:00 Am | I32: 5416 | J32: Colling tower material shifting | K32: New chiller building | L32: Fluid-line | M32: Akshey | N32: Tajinder | O32: No | P32: General work | Q32: High Risk
A33: 32 | B33: 46171.806 | C33: 46171.807 | D33: anonymous | F33: 46171 | G33: 2:45 Pm | I33: 5418 | J33: Chiller and hot well tank shifting | K33: New chiller building | L33: Fluid-line | M33: Danish | N33: Ajay | O33: No | P33: General work | Q33: High Risk
A34: 33 | B34: 46171.807 | C34: 46171.809 | D34: anonymous | F34: 46171 | G34: 9:37 Am | I34: 5414 | J34: Welding and cutting work for support | K34: Nitrogen back side | L34: Fluid-line | M34: Akash | N34: Akshey | O34: No | P34: Hot work, General work | Q34: High Risk
... A55: 54 | B55: 46174.428 | C55: 46174.431 | D55: anonymous | F55: 46174 | G55: 09:45 am | I55: 5020 | J55: Toe guard fixing, welding, grinding, cutting, scaffold erection & dismantle, housekeeping, material shifting | K55: Evaporator building | L55: Esspee | M55: Ajay | N55: Surender | O55: No | P55: General work, Hot work, Work at height | Q55: Low Risk
A56: 55 | B56: 46174.446 | C56: 46174.45 | D56: anonymous | F56: 46174 | G56: 9:40Am | I56: 5169 | J56: Block work,shuttering work. D-shuttring work welding & concreting work | K56: Canteen area& air compressor, chiller areas | L56: Crescon | M56: Danish | N56: Manoj | O56: No | P56: General work, Hot work, Work at height | Q56: High Risk | R56: Mandatory ppe's proper safe access and housekeeping
A57: 56 | B57: 46174.451 | C57: 46174.453 | D57: anonymous | F57: 46174 | G57: 09:48 am | I57: 5168 | J57: Pipe rack erection lifting & shifting unloading using farana boom lift | K57: G-section canteen area | L57: Crescon | M57: Manoj | N57: Danish | O57: No | P57: Work at height | Q57: High Risk | R57: Use of PPE's job specific & erection area barricade
A58: 57 | B58: 46174.821 | C58: 46174.822 | D58: anonymous | F58: 46174 | G58: 9:20 | I58: 3551 | J58: Plateform shifting and erection scaffolding erection and Dismantle | K58: Evaporator | L58: GEA | M58: Ajay | N58: Surender | O58: No | P58: General work, Hot work, Work at height | Q58: Medium Risk
A59: 58 | B59: 46174.869 | C59: 46174.871 | D59: anonymous | F59: 46174 | G59: 10:15 Am | I59: 5428 | J59: Commissioning work | K59: MWRS chiller area | L59: Fluid-line | M59: Akash | N59: Ajay | O59: No | P59: General work, Hot work, Work at height | Q59: High Risk
A60: 59 | B60: 46174.871 | C60: 46174.872 | D60: anonymous | F60: 46174 | G60: 10,:11 | I60: 5429 | J60: Pipe structure fabrication and installation | K60: New chiller area | L60: Fluid-line | M60: Akash | N60: Ajay | O60: No | P60: General work, Hot work, Work at height | Q60: High Risk
A61: 60 | B61: 46174.872 | C61: 46174.873 | D61: anonymous | F61: 46174 | G61: 10:18 Am | I61: 5430 | J61: Ammonia line hydrotest | K61: Nitrogen area back side | L61: Fluid-line | M61: Akash | N61: Ajay | O61: No | P61: Hot work, General work | Q61: High Risk
A62: 61 | B62: 46174.873 | C62: 46174.874 | D62: anonymous | F62: 46174 | G62: 10:16 Am | I62: 5431 | J62: Chiller pipe line insulation work | K62: Shaft room | L62: Fluid-line | M62: Akash | N62: Ajay | O62: No | P62: General work | Q62: Medium Risk
A63: 62 | B63: 46174.874 | C63: 46174.875 | D63: anonymous | F63: 46174 | G63: 13:15 | I63: 5433 | J63: Pipe cutting welding work | K63: Nitrogen back side | L63: Fluid-line | M63: Akshey | N63: Ajay | O63: No | P63: Hot work, General work | Q63: High Risk
A64: 63 | B64: 46174.875 | C64: 46174.875 | D64: anonymous | F64: 46174 | G64: 16:30 | I64: 5434 | J64: Shifting and positioning of hot well tank | K64: New chiller area | L64: Fluid-line | M64: Akash | N64: Ajay | O64: No | P64: General work, Work at height | Q64: High Risk
A65: 64 | B65: 46175.399 | C65: 46175.4 | D65: anonymous | F65: 46175 | G65: 9:15 | I65: 3552 | J65: Plateform erection & shifting scaffolding erection and Dismantle | K65: Evaporator | L65: GEA | M65: Akshey | N65: Surender | O65: No | P65: General work, Hot work, Work at height | Q65: Medium Risk
A66: 65 | B66: 46175.405 | C66: 46175.406 | D66: anonymous | F66: 46175 | G66: 9:15 | I66: 5436 | J66: Pipeline and structure fabrication support installation and material shifting | K66: New chiller area | L66: Fluid-line | M66: Tajinder | N66: Akshey | O66: No | P66: General work, Hot work, Work at height | Q66: High Risk
A67: 66 | B67: 46175.415 | C67: 46175.417 | D67: anonymous | F67: 46175 | G67: 09:40Am | I67: 5061 | J67: Water Flushing, insulation cladding fixing, Material shifting. | K67: Oil Blending to Reception. | L67: SPX | M67: Tajinder | N67: Akash | O67: No | P67: General work, Work at height | Q67: Low Risk
...

Sheet HighRiskObs
A1: High risk Observation categories | C1: Count | F1: High risk observations
A2: {=_xlfn.VSTACK(_xlfn._xlws.FILTER(PTWAuditTable[1st Category of Observation],VALUE(PTWAuditTable[1st Severity])>=4,""),_xlfn._xlws.FILTER(PTWAuditTable[2nd Category of Observation],VALUE(PTWAuditTable[2nd Severity])>=4,""),_xlfn._xlws.FILTER(PTWAuditTable[3rd Category of Observation],VALUE(PTWAuditTable[3rd Severity])>=4,""),_xlfn._xlws.FILTER(PTWAuditTable[4th Category of Observation],VALUE(PTWAuditTable[4th Severity])>=4,""),_xlfn._xlws.FILTER(PTWAuditTable[5th Category of Observation],VALUE(PTWAuditTable[5th Severity])>=4,""))} -> Behavioral Issue -Unsafe Act | C2: {=_xlfn._xlws.SORT(_xlfn.LET(_xlpm.obs,_xlfn.ANCHORARRAY(A2),_xlpm.u,_xlfn.UNIQUE(_xlpm.obs),_xlfn.HSTACK(_xlpm.u,COUNTIF(_xlpm.obs,_xlpm.u))),2,-1)} | D2: 4 | F2: {=_xlfn.VSTACK(_xlfn._xlws.FILTER(PTWAuditTable[1st Observation],VALUE(PTWAuditTable[1st Severity])>=4,""),_xlfn._xlws.FILTER(PTWAuditTable[2nd Observation],VALUE(PTWAuditTable[2nd Severity])>=4,""),_xlfn._xlws.FILTER(PTWAuditTable[3rd Observation],VALUE(PTWAuditTable[3rd Severity])>=4,""),_xlfn._xlws.FILTER(PTWAuditTable[4th Observation],VALUE(PTWAuditTable[4th Severity])>=4,""),_xlfn._xlws.FILTER(PTWAuditTable[5th Observation],VALUE(PTWAuditTable[5th Severity])>=4,""))} -> Person standing on block at height unsafe
A3: Electrical safety | C3: Behavioral Issue -Unsafe Act | D3: 1 | F3: Lifting aLifting activity started without protecting the electrical panel.
C4: Electrical safety | D4: 1

Sheet ContractorObs
A1: Contractor | B1: Observations | E1: Contractor | F1: Observations
A2: {=_xlfn._xlws.SORT(_xlfn.UNIQUE(_xlfn._xlws.FILTER(PTWAuditTable[Contractor],PTWAuditTable[Contractor]<>"")))} -> Aalanaa | B2: =COUNTIFS(PTWAuditTable[Contractor],A2,PTWAuditTable[1st Observation],"<>")+COUNTIFS(PTWAuditTable[Contractor],A2,PTWAuditTable[2nd Observation],"<>")+COUNTIFS(PTWAuditTable[Contractor],A2,PTWAuditTable[3rd Observation],"<>")+COUNTIFS(PTWAuditTable[Contractor],A2,PTWAuditTable[4th Observation],"<>")+COUNTIFS(PTWAuditTable[Contractor],A2,PTWAuditTable[5th Observation],"<>") -> 3 | E2: {=_xlfn._xlws.SORT(A2:B15,2,-1)} -> Fluidline | F2: 19
A3: CCEPL | B3: =COUNTIFS(PTWAuditTable[Contractor],A3,PTWAuditTable[1st Observation],"<>")+COUNTIFS(PTWAuditTable[Contractor],A3,PTWAuditTable[2nd Observation],"<>")+COUNTIFS(PTWAuditTable[Contractor],A3,PTWAuditTable[3rd Observation],"<>")+COUNTIFS(PTWAuditTable[Contractor],A3,PTWAuditTable[4th Observation],"<>")+COUNTIFS(PTWAuditTable[Contractor],A3,PTWAuditTable[5th Observation],"<>") -> 5 | E3: Crescon | F3: 11
A4: Crescon | B4: =COUNTIFS(PTWAuditTable[Contractor],A4,PTWAuditTable[1st Observation],"<>")+COUNTIFS(PTWAuditTable[Contractor],A4,PTWAuditTable[2nd Observation],"<>")+COUNTIFS(PTWAuditTable[Contractor],A4,PTWAuditTable[3rd Observation],"<>")+COUNTIFS(PTWAuditTable[Contractor],A4,PTWAuditTable[4th Observation],"<>")+COUNTIFS(PTWAuditTable[Contractor],A4,PTWAuditTable[5th Observation],"<>") -> 11 | E4: CCEPL | F4: 5
A5: Esspee | B5: =COUNTIFS(PTWAuditTable[Contractor],A5,PTWAuditTable[1st Observation],"<>")+COUNTIFS(PTWAuditTable[Contractor],A5,PTWAuditTable[2nd Observation],"<>")+COUNTIFS(PTWAuditTable[Contractor],A5,PTWAuditTable[3rd Observation],"<>")+COUNTIFS(PTWAuditTable[Contractor],A5,PTWAuditTable[4th Observation],"<>")+COUNTIFS(PTWAuditTable[Contractor],A5,PTWAuditTable[5th Observation],"<>") -> 5 | E5: Esspee | F5: 5
A6: Fluidline | B6: =COUNTIFS(PTWAuditTable[Contractor],A6,PTWAuditTable[1st Observation],"<>")+COUNTIFS(PTWAuditTable[Contractor],A6,PTWAuditTable[2nd Observation],"<>")+COUNTIFS(PTWAuditTable[Contractor],A6,PTWAuditTable[3rd Observation],"<>")+COUNTIFS(PTWAuditTable[Contractor],A6,PTWAuditTable[4th Observation],"<>")+COUNTIFS(PTWAuditTable[Contractor],A6,PTWAuditTable[5th Observation],"<>") -> 19 | E6: GEA | F6: 5
A7: GEA | B7: =COUNTIFS(PTWAuditTable[Contractor],A7,PTWAuditTable[1st Observation],"<>")+COUNTIFS(PTWAuditTable[Contractor],A7,PTWAuditTable[2nd Observation],"<>")+COUNTIFS(PTWAuditTable[Contractor],A7,PTWAuditTable[3rd Observation],"<>")+COUNTIFS(PTWAuditTable[Contractor],A7,PTWAuditTable[4th Observation],"<>")+COUNTIFS(PTWAuditTable[Contractor],A7,PTWAuditTable[5th Observation],"<>") -> 5 | E7: Aalanaa | F7: 3
A8: KC flooring | B8: =COUNTIFS(PTWAuditTable[Contractor],A8,PTWAuditTable[1st Observation],"<>")+COUNTIFS(PTWAuditTable[Contractor],A8,PTWAuditTable[2nd Observation],"<>")+COUNTIFS(PTWAuditTable[Contractor],A8,PTWAuditTable[3rd Observation],"<>")+COUNTIFS(PTWAuditTable[Contractor],A8,PTWAuditTable[4th Observation],"<>")+COUNTIFS(PTWAuditTable[Contractor],A8,PTWAuditTable[5th Observation],"<>") -> 2 | E8: Satnam | F8: 3
A9: Satnam | B9: =COUNTIFS(PTWAuditTable[Contractor],A9,PTWAuditTable[1st Observation],"<>")+COUNTIFS(PTWAuditTable[Contractor],A9,PTWAuditTable[2nd Observation],"<>")+COUNTIFS(PTWAuditTable[Contractor],A9,PTWAuditTable[3rd Observation],"<>")+COUNTIFS(PTWAuditTable[Contractor],A9,PTWAuditTable[4th Observation],"<>")+COUNTIFS(PTWAuditTable[Contractor],A9,PTWAuditTable[5th Observation],"<>") -> 3 | E9: KC flooring | F9: 2
D10: This will fill if more contractors are added | E10: 0 | F10: 0
E11: 0 | F11: 0
E12: 0 | F12: 0
E13: 0 | F13: 0
E14: 0 | F14: 0
E15: 0 | F15: 0

Sheet PTW Audit
A1: Completion time | B1: Date | C1: Auditor Name | D1: Contractor type | E1: PTW No | F1: Type of PTW | G1: Contractor | H1: Area | I1: Issuer | J1: Authorizer | K1: 1st Observation | L1: 1st Category of Observation | M1: 1st Severity | N1: 2nd Observation | O1: 2nd Category of Observation | P1: 2nd Severity | Q1: 3rd Observation | R1: 3rd Category of Observation | S1: 3rd Severity | T1: 4th Observation | U1: 4th Category of Observation | V1: 4th Severity | W1: 5th Severity | X1: 5th Observation | Y1: 5th Category of Observation | AA1: Audited
A2: 46203.687 | B2: 46203 | C2: ANKUR KUMAR | D2: Project | E2: 3684 | F2: Height Work | G2: Crescon | H2: Ebevorator | I2: Danish | J2: Akash | K2: Emergency exit pathway not clear | L2: Housekeeping | M2: 3 | N2: Cable routing not maintained as per standard | O2: Electrical safety | P2: 2 | AA2: =COUNTA(_xlfn.UNIQUE(PTWAuditTable[PTW No])) -> 33
A3: 46203.714 | B3: 46203 | C3: ANKUR KUMAR | D3: Project | E3: 3838 | F3: Hot work | G3: Aalanaa | H3: Ebevorator | I3: Danish | J3: Akash | K3: Work planned not shared | L3: Wrong Work Permit/No Permit | M3: 3 | N3: Fire watcher name and signed not mentioned on permit | O3: Fire Safety | P3: 3
A4: 46204.002 | B4: 46203 | C4: Anil kumar | D4: Project | E4: 715 | F4: Lifting | G4: GEA | H4: Evaporator area | I4: Danish | J4: manoj | K4: Permit not closed after work completed | L4: Closing & Authorization Issues | M4: 2
A5: 46204.004 | B5: 46203 | C5: Anil Kumar | D5: Project | E5: 3903 | F5: General | G5: GEA | H5: Evaporator area | I5: Danish | J5: manoj | K5: Meterial shifting without Adiqute PPE's (Hand glaves) | L5: PPE | M5: 3
A6: 46204.504 | B6: 46204 | C6: Sahil | D6: Plant | E6: 21346 | F6: Hot work | G6: Satnam | H6: Tca ground floor | I6: Saurav | J6: Ajay | K6: Barrication of the are not done | L6: Barricading | M6: 3 | N6: Person observed without googles | O6: PPE | P6: 3
A7: 46204.52 | B7: 46204 | C7: Sahil | D7: Project | E7: 4515 | F7: Hot work | G7: Fluidline | H7: New chiller area | I7: Akshay | J7: Akash | K7: Combustible material kept in the hot work area | L7: Fire Safety | M7: 3 | N7: Person observed without google working near cutting & grinding work | O7: PPE | P7: 3 | Q7: Barrication of the area is not adequate | R7: Barricading | S7: 2
A8: 46204.523 | B8: 46204 | C8: Sahil | D8: Project | E8: 3687 | F8: Height Work | G8: Crescon | H8: New chiller building | I8: Akshay | J8: Akash | K8: Height work more than 6m started without safety authorization | L8: Closing & Authorization Issues | M8: 3
A9: 46204.526 | B9: 46204 | C9: Sahil | D9: Project | E9: 3686 | F9: General | G9: Crescon | H9: New chiller area | I9: Shahnawaj | J9: Akash | K9: Worker observed standing on scaffolding rungs without having platform | L9: Behavioral Issue -Unsafe Act | M9: 3 | N9: Worker observed without tieng safety harness while working at height | O9: Behavioral Issue -Unsafe Act | P9: 3
A10: 46204.961 | B10: 46204 | C10: ANKUR KUMAR | D10: Project | E10: 3957 | F10: Hot work | G10: Esspee | H10: Ebevorator terrace | I10: Nikhil | J10: Danish | K10: During using grinder worker not wear gloves and ear plugs | L10: PPE | M10: 3
A11: 46205.121 | B11: 46204 | C11: ANKUR KUMAR | D11: Project | E11: 3686 | F11: Height Work | G11: Crescon | H11: New chiller plant | I11: Nikhil | J11: Shahnawaj | K11: Scaffolding planks stacked on scaffolding plateform improper manners | L11: Behavioral Issue -Unsafe Act | M11: 3
A12: 46205.523 | B12: 46205 | C12: Anil kumar | D12: Project | E12: 720 | F12: Lifting | G12: GEA | H12: Evaporator | I12: manoj | J12: Ajay | K12: Permit end date and time not maintained. | L12: Wrong Work Permit/No Permit | M12: 2
A13: 46205.53 | B13: 46205 | C13: Anil kumar | D13: Project | E13: 4011 | F13: Hot work | G13: CCEPL | H13: Refrigeration out side near evaporator area | I13: Ajay | J13: Akash | K13: Worker using hammer without hand gloves. | L13: PPE | M13: 3
A14: 46205.531 | B14: 46205 | C14: Anil kumar | D14: Project | E14: 4009 | F14: Height Work | G14: CCEPL | H14: Project office terrace | I14: Ajay | J14: Akash | K14: Safety harness found in damaged condition. | L14: PPE | M14: 2
A15: 46206.072 | B15: 46205 | C15: ANKUR KUMAR | D15: Project | E15: 4011 | F15: Hot work | G15: CCEPL | H15: Refrigerator area | I15: Ajay | J15: Akash | K15: Cable routing not proper at site | L15: Electrical safety | M15: 2
A16: 46206.075 | B16: 46205 | C16: ANKUR KUMAR | D16: Project | E16: 3960 | F16: Hot work | G16: Esspee | H16: Evaporator terrace | I16: Abhay | J16: Nikhil | K16: Fire extinguisher not available at site during hot work | L16: Fire Safety | M16: 3 | N16: Light not sufficient for work | O16: Inspection and Calibration | P16: 3
A17: 46206.076 | B17: 46205 | C17: ANKUR KUMAR | D17: Project | E17: 3906 | F17: Hot work | G17: GEA | H17: Evaporator | I17: manoj | J17: Ajay | K17: Using grinder ear plugs not wear | L17: PPE | M17: 2
A18: 46206.486 | B18: 46206 | C18: Anil kumar | D18: Plant | E18: 23926 | F18: Height Work | G18: Satnam | H18: Oil blending near staircase | I18: Sourav | J18: Ajay | K18: The work permit was signed before its official issue time. The permit was authorized at 9:20, while the issue time is 10:20. | L18: Closing & Authorization Issues | M18: 3
A19: 46206.488 | B19: 46206 | C19: Anil kumar | D19: Plant | E19: 23009 | F19: Hot work | G19: Esspee | H19: Utility | I19: Jibran | J19: Pardeep saho | K19: Permit location not mentioned | L19: Closing & Authorization Issues | M19: 2
A20: 46206.49 | B20: 46206 | C20: ANIL KUMAR | D20: Project | E20: 3793 | F20: Height Work | G20: Fluidline | H20: Refrigeration | I20: Nikhil | J20: Akash | K20: Scaffold dismantling in progress. Red Tag displayed. | L20: Behavioral Issue -Unsafe Act | M20: 3
A21: 46206.493 | B21: 46206 | C21: ANIL kumar | D21: Project | E21: 4013 | F21: Hot work | G21: CCEPL | H21: Refrigeration | I21: Varun sodhi | J21: Nikhil | K21: Sharp edge on the DB canopy is not covered. | L21: Powered and Hand Tools | M21: 3
A22: 46206.494 | B22: 46206 | C22: Anil kumar | D22: Project | E22: 4520 | F22: General | G22: Fluidline | H22: Refrigeration terrace | I22: Nikhil | J22: Akash | K22: Contractor supervisor signed missing. | L22: Wrong Work Permit/No Permit | M22: 1
A23: 46206.495 | B23: 46206 | C23: Anil kumar | D23: Project | E23: 4519 | F23: Height Work | G23: Fluidline | H23: New chiller building | I23: Nikhil | J23: Akash | K23: Fire watcher person signed missing. | L23: Fire Safety | M23: 3 | N23: Safety harness serial number not mentioned. | O23: Behavioral Issue -Unsafe Act | P23: 2
A24: 46207.081 | B24: 46206 | C24: ANKUR KUMAR | D24: Project | E24: 3693 | F24: General | G24: Crescon | H24: New chiller | I24: Varun | J24: Nikhil | K24: Person standing on block at height unsafe | L24: Behavioral Issue -Unsafe Act | M24: 4
A25: 46207.082 | B25: 46206 | C25: ANKUR KUMAR | D25: Project | E25: 4519 | F25: Hot work | G25: Fluidline | H25: New chiller | I25: Nikhil | J25: Akash | K25: Combustible material not covered | L25: Fire Safety | M25: 3
A26: 46207.083 | B26: 46206 | C26: ANKUR KUMAR | D26: Project | E26: 4013 | F26: Hot work | G26: CCEPL | H26: Refrigerator | I26: Varun | J26: Nikhil | K26: Sharp edges not covered | L26: Behavioral Issue -Unsafe Act | M26: 2
A27: 46207.576 | B27: 46207 | C27: anil kumar | D27: Plant | E27: 23103 | F27: General | G27: KC flooring | H27: HCA | I27: Dinesh | J27: Jibran | K27: Contractor supervisor signed missing | L27: Wrong Work Permit/No Permit | M27: 2 | N27: Jsa and MOS number not maintained | O27: Wrong Work Permit/No Permit | P27: 2
A28: 46207.619 | B28: 46207 | C28: Anil kumar | D28: Project | E28: 3909 | F28: Height Work | G28: GEA | H28: Evaporator | I28: Sunny | J28: Surender | K28: Lifting aLifting activity started without protecting the electrical panel. | L28: Electrical safety | M28: 4
A29: 46207.621 | B29: 46207 | C29: Anil kumar | D29: Project | E29: 4523 | F29: Height Work | G29: Fluidline | H29: New chiller | I29: Akshay | J29: Akash | K29: Fire watcher person signed missing | L29: Fire Safety | M29: 2
A30: 46207.84 | B30: 46207 | C30: ANKUR KUMAR | D30: Project | E30: 3694 | F30: Height Work | G30: Crescon | H30: New chiller | I30: Varun | J30: Akash | K30: Sharp edges not covered | L30: Inspection and Calibration | M30: 2
A31: 46207.842 | B31: 46207 | C31: ANKUR KUMAR | D31: Project | E31: 4523 | F31: Hot work | G31: Fluidline | H31: New chiller | I31: Akshay | J31: Akash | K31: Person not wear helmet and reflection jecket inside chiller | L31: PPE | M31: 3 | N31: Scaffolding tag not apply,loose ledger, base jeck not installed worker working on it | O31: Behavioral Issue -Unsafe Act | P31: 3 | Q31: Paint was kept near by Hot work | R31: Fire Safety | S31: 3
A32: 46209.929 | B32: 46210 | C32: ANKUR KUMAR | D32: Project | E32: 3976 | F32: Height Work | G32: Esspee | H32: Ebevorator | I32: Ajay | J32: Varun | K32: Task JSA not available | L32: TBT /JSA | M32: 3
A33: 46209.93 | B33: 46209 | C33: ANKUR KUMAR | D33: Project | E33: 4529 | F33: Hot work | G33: Fluidline | H33: New chiller | I33: Akshay | J33: Varun | K33: Hot work going on combustible material not covered | L33: Fire Safety | M33: 3
A34: 46209.931 | B34: 46209 | C34: ANKUR KUMAR | D34: Project | E34: 3697 | F34: Height Work | G34: Crescon | H34: New chiller | I34: Varun | J34: Akash | K34: Scaffolder standing on unsafe platform | L34: Behavioral Issue -Unsafe Act | M34: 3
A35: 46210.847 | B35: 46210 | C35: Ankur kumar | D35: Project | E35: 4202 | F35: Height Work | G35: Crescon | H35: Ebevorator | I35: Akshay | J35: Ajay | K35: Pathway is not clear Trip hazard observed | L35: Housekeeping | M35: 2 | N35: Light not sufficient for work | O35: Inspection and Calibration | P35: 3
A36: 46210.849 | B36: 46210 | C36: Ankur kumar | D36: Project | E36: 4205 | F36: Height Work | G36: Aalanaa | H36: Ebevorator | I36: Varun | J36: Varun | K36: Scaffolding tag not apply | L36: Inspection and Calibration | M36: 3
A37: 46210.85 | B37: 46210 | C37: Ankur kumar | D37: Project | E37: 4533 | F37: Hot work | G37: Fluidline | H37: New chiller | I37: Akshay | J37: Ajay | K37: Fire extinguisher not present near by Hot work | L37: Fire Safety | M37: 3
A38: 46211.925 | B38: 46212 | C38: Ankur kumar | D38: Project | E38: 4536 | F38: Hot work | G38: Fluidline | H38: New chiller | I38: Akshay | J38: Varun | K38: Cable routing not proper at site and S book not used | L38: Electrical safety | M38: 3
A39: 46212.855 | B39: 46213 | C39: Ankur kumar | D39: Project | E39: 4539 | F39: Hot work | G39: Fluidline | H39: New chiller | I39: Abhay | J39: Varun | K39: Loose electrical cables are improperly routed over scaffold and pipeline, creating trip and cable damage hazards. | L39: Fire Safety | M39: 3 | N39: Wet and slippery floor due to water | O39: Housekeeping | P39: 2 | Q39: Combustible material not covered with fire blanket | R39: Fire Safety | S39: 3 | T39: Worker used unsafe platform at 1 meter height | U39: Behavioral Issue -Unsafe Act

Sheet Sheet1
G1: 46210 | H1: Rajesh | I1: Zone 3 | J1: Contractor Shed and Periphery | K1: Done
G2: 46210 | H2: Deepanshu | I2: Zone 4 | J2: Oil Blending, Panel, Refrigeration Building & Roof | K2: NA
A3: 46210 | B3: Rohit | C3: Zone 1 | D3: Chiller and Oil Injection | E3: Leave | G3: 46210 | H3: Vivek | I3: Zone 3 | J3: Contractor Shed and Periphery | K3: Not Done
A4: 46210 | B4: Vinoth | C4: Zone 2 | D4: Evaporator Building | E4: Not Done | G4: 46210 | H4: Paras | I4: Zone 4 | J4: Oil Blending, Panel, Refrigeration Building & Roof | K4: Done
A5: 46210 | B5: Arun | C5: Zone 3 | D5: Contractor Shed and Periphery | E5: Not Done | G5: 46210 | H5: Nikunj | I5: Zone 1 | J5: Chiller and Oil Injection | K5: Not Done
A6: 46210 | B6: Monty | C6: Zone 4 | D6: Oil Blending, Panel, Refrigeration Building & Roof | E6: Not Done | G6: 46210 | H6: Om Prakash | I6: Zone 4 | J6: Oil Blending, Panel, Refrigeration Building & Roof | K6: Not Done
A7: 46210 | B7: Sahil | C7: Zone 1 | D7: Chiller and Oil Injection | E7: Done
A8: 46210 | B8: Anil | C8: Zone 2 | D8: Evaporator Building | E8: Leave

Sheet PTW Dashboard Data
A1: No. of work permits issued | B1: No. of work permits closed | C1: No. of work permits audited | D1: No. of observations | E1: Critical observations | F1: Compliance % | G1: No. of high risk issued | H1: High risk executed | I1: Obs in high risk permits
A2: ='[1]PTW Record'!$Q$3 -> 2907 | B2: ='[1]PTW Record'!$R$3 -> 2832 | C2: ='PTW Audit'!AA2 -> 33 | D2: =COUNTA(PTWAuditTable[1st Observation])+COUNTA(PTWAuditTable[2nd Observation])+COUNTA(PTWAuditTable[3rd Observation])+COUNTA(PTWAuditTable[4th Observation])+COUNTA(PTWAuditTable[5th Observation]) -> 53 | E2: {=SUMPRODUCT(--(VALUE(PTWAuditTable[1st Severity])>=4))+SUMPRODUCT(--(VALUE(PTWAuditTable[2nd Severity])>=4))+SUMPRODUCT(--(VALUE(PTWAuditTable[3rd Severity])>=4))+SUMPRODUCT(--(VALUE(PTWAuditTable[4th Severity])>=4))+SUMPRODUCT(--(VALUE(PTWAuditTable[5th Severity])>=4))} -> 2 | F2: =((A2-D2)/(A2))*100 -> 98.176815 | G2: ='[1]PTW Record'!$S$3 -> 321 | H2: ='[1]PTW Record'!$T$3 -> 314 | I2: ='[1]PTW Record'!$U$3 -> 22
A4: Top 3 contractor vs obs | C4: Top 3 observations | D4: Top 3 categories
A5: =ContractorObs!E2 -> Fluidline | B5: =ContractorObs!F2 -> 19 | C5: =HighRiskObs!F2 -> Person standing on block at height unsafe | D5: =HighRiskObs!C3 -> Behavioral Issue -Unsafe Act
A6: =ContractorObs!E3 -> Crescon | B6: =ContractorObs!F3 -> 11 | C6: =HighRiskObs!F3 -> Lifting aLifting activity started without protecting the electrical panel. | D6: =HighRiskObs!C4 -> Electrical safety
A7: =ContractorObs!E4 -> CCEPL | B7: =ContractorObs!F4 -> 5 | C7: =HighRiskObs!F4 | D7: =HighRiskObs!C5 -> 0

Sheet CSFA Dashboard
